Workbook

Sheet TOPLAM
A1: Sıra | B1: Araştırma Görevlisi | C1: Puanı | F1: {=_xlfn._xlws.SORT(Tablo1[],3,-1,FALSE)} -> 1 | G1: Begüm DOGANAY | H1: 279
A2: 1 | B2: Begüm DOGANAY | C2: ='Begüm DOGANAY'!E113 -> 279 | F2: 9 | G2: Y.Tarık MUTLU | H2: 274
A3: 2 | B3: Cenk KAYA | C3: ='Cenk KAYA'!E83 -> 33 | F3: 3 | G3: Fatih NACAR | H3: 267
A4: 3 | B4: Fatih NACAR | C4: ='Fatih NACAR'!E99 -> 267 | F4: 8 | G4: Samet BİÇEN | H4: 260
A5: 4 | B5: Merve GÜL ÇIVGIN | C5: ='Merve GÜL ÇIVGIN'!E106 -> 208 | F5: 4 | G5: Merve GÜL ÇIVGIN | H5: 208
A6: 5 | B6: Muhittin ORHAN | C6: ='Muhittin ORHAN'!E82 -> 166 | F6: 10 | G6: Sinan COŞKUN | H6: 200
A7: 6 | B7: Ö. Berkehan İnal | F7: 7 | G7: Rukiye GÜLMEZ | H7: 174
A8: 7 | B8: Rukiye GÜLMEZ | C8: ='Rukiye GÜLMEZ'!E89 -> 174 | F8: 5 | G8: Muhittin ORHAN | H8: 166
A9: 8 | B9: Samet BİÇEN | C9: ='Samet BİÇEN'!E56 -> 260 | F9: 2 | G9: Cenk KAYA | H9: 33
A10: 9 | B10: Y.Tarık MUTLU | C10: ='Y.Tarık MUTLU'!E133 -> 274 | F10: 6 | G10: Ö. Berkehan İnal | H10: 0
A11: 10 | B11: Sinan COŞKUN | C11: ='Sinan COŞKUN'!E97 -> 200
A14: Her araştırma görevlisine görevler adil verilmeli.
A15: 1 Temmuz 2025'ten itibaren puan tablosu başlayacaktır.
A19: 14686 | B19: MEK | C19: 205E | D19: Engineering Mechanics | E19: Banu Tansel Büyükçelebi | F19: Cumartesi | G19: 15:00-17:00 | H19: 46039
A20: *1.dönem bu sınavda güverteye 1 argör borç verildi. 2.dönem haftasonu sınavında güverteden 1 argör fazla yazılacak.
B22: KIM101E | C22: Yasin Arslanoğlu | D22: Makineden girildi | F22: Cumartesi | G22: 10:00-12:00 | H22: 46130
A24: 25.04.2026 Fizik Sınavı için 1 kişi güverteden talep edildi.

Sheet Ar.Gör. Bilgileri
A1: Fakülte | B1: Bölüm | C1: İsim | D1: Cep Telefonu | E1: E-posta
A2: DZ | B2: GMI | C2: Begüm DOGANAY | D2: 5071432107 | E2: doganaybe@itu.edu.tr
A3: DZ | B3: GMI | C3: Cenk KAYA | E3: cenkkaya@itu.edu.tr
A4: DZ | B4: GMI | C4: Fatih NACAR | D4: 5065813277 | E4: nacar16@itu.edu.tr
A5: DZ | B5: GMI | C5: Merve GÜL ÇIVGIN | D5: 5425111429 | E5: gulme@itu.edu.tr
A6: DZ | B6: GMI | C6: Muhittin ORHAN | D6: 5545762801 | E6: orhanm17@itu.edu.tr
A7: DZ | B7: GMI | C7: Ö. Berkehan İNAL | E7: inalo@itu.edu.tr
A8: DZ | B8: GMI | C8: Rukiye GÜLMEZ | D8: 5070963781 | E8: gulmezr@itu.edu.tr
A9: DZ | B9: GMI | C9: Samet BİÇEN | D9: 5522087166 | E9: sbicen@itu.edu.tr
A10: DZ | B10: GMI | C10: Sinan COŞKUN | D10: 5555240033 | E10: coskunm19@itu.edu.tr
A11: DZ | B11: GMI | C11: Y.Tarık MUTLU | D11: 5319201098 | E11: ymutlu@itu.edu.tr

Sheet Puan Baremi
A1: Gözetmenlik Puanlama Sistemi
A2: Tuzla haftaiçi 1 sınav | B2: 1 Puan
A3: Tuzla haftaiçi 1 sınav (mesai dışı) | B3: 2 Puan
A4: Tuzla haftaiçi (Yeterlik sınavı) | B4: 4 Puan
A5: Tuzla haftasonu 1 sınav | B5: 2 Puan
A6: Tuzla haftaiçi 1 sınav (havuz dersleri) | B6: 2 Puan
A7: Tuzla haftasonu 1 sınav (havuz dersleri) | B7: 3 puan
A8: Maslak haftaiçi 1 sınav | B8: 4 Puan
A9: Maslak haftasonu 1 sınav | B9: 5 puan
A10: Görev Puanlama Sistemi
A11: Lisans bitirme tezi (adet) | B11: 2 Puan
A12: Yüksek lisans bitirme tezi (adet) | B12: 3 puan
A13: Liman Komisyonu | B13: 1 Puan
A14: Not Komisyonu (40-50 kişi) | B14: 3 puan
A15: Not Komisyonu (max 10 kişi) | B15: 2 Puan
A16: Fakülte Gezisi (1-2 saat) | B16: 2 Puan
A17: Fakülte Gezisi (2 Saat üzeri) | B17: 3 Puan
A18: Tanıtım günleri (Ayazağa-Haftaiçi) | B18: 8 Puan
A19: Tanıtım günleri (Fakülte-Haftaiçi) | B19: 6 Puan
A20: Tanıtım günleri (Ayazağa-Haftasonu) | B20: 10 Puan
A21: Tanıtım günleri (Fakülte-Haftasonu) | B21: 8 Puan
A22: Toplantı (saat başına ve yoğunluğuna göre) | B22: 1 Puan
... A34: 1 dönem ders asiste etmek | B34: 10 Puan

Sheet Haftalık Program
A1: GÜZ DÖNEMİ
A2: Araştırma Görevlisi | B2: PAZARTESİ | C2: SALI | D2: ÇARŞAMBA | E2: PERŞEMBE | F2: CUMA
A3: Begüm DOGANAY | C3: GMIM Lisansüstü 1000-1200
A4: Cenk KAYA
A5: Fatih NACAR | B5: 0830/1730 Atölye | C5: 1330/1530 Malzeme Bilgisi
A6: Merve GÜL ÇIVGIN | C6: GMIM Lisansüstü 1000-1200
A7: Muhittin ORHAN
A8: Ö. Berkehan İnal
A9: Rukiye GÜLMEZ | F9: 0830/1130ERS1
A10: Samet BİÇEN | D10: 0830/1130 GMI 384E ve 1330/1530 GMI 324E | E10: 0830/1130 GMI 454 ve 0830/1730 GMI 324 | F10: TEKNOPARK GÖREVİ | H10: "1. DUI 405 GEMİ MAKİNALARI 1130/1330 2. GMI484E ERS II 1430/1730" | J10: "1. GMI484E ERS II 0830/1130 2. GMI484E ERS II 1230/1530" | L10: Teknopark görevlendirmesi (08:30 - 17:30)
A11: Y.Tarık MUTLU | C11: YTÜ DERS | E11: YTÜ DERS | H11: YTÜ doktora dersleri | I11: YTÜ doktora dersleri
A12: Sinan COŞKUN | C12: MASLAK DERS | J12: "GMI 320E - Ship Construction And Stability "

Sheet Genel Görevler
A1: ARGÖR DAİMİ GÖREVLERİ
A2: Ad-Soyadı | B2: Görevi
A3: Begüm Doganay | B3: 1. Kalite Komisyonu | D3: 1. NATO'da görevli
B4: 2. Simülatör yardımcıılığı
B5: 3. İTÜ DF Makine Ar.Gör.Temsilciliği
B6: 4. Liman Komisyonu
B7: 5. Not Komisyonu
B8: 6. GMIM Lisansüstü
B9: 7. 2.Sınıf amiri
B10: 7. Denizatı görevlendirmesi
A11: Fatih Nacar | B11: 1. Kalite Komisyonu | D11: 1. NATO'da görevli
B12: 2. Staj Komisyonu
B13: 3. Liman Komisyonu
B14: 4. Not Komisyonu
B15: 5. 3.Sınıf amiri
B16: 6. Denizatı görevlendirmesi
A17: Merve Gül Çıvgın | B17: 1. Burs Komisyonu | D17: 1. NATO'da görevli
B18: 2. Simülatör Sorumlusu
B19: 3. SEM
B20: 4. GMIM Lisansüstü
A21: Muhittin Orhan | B21: 1. İTÜ df kalite ve çevre komisyonu
B22: 2. Temel bilimler için kalite koordinatörü
B23: 3. İTÜ DF adına yıllık e-bülten hazırlanma
B24: 4. Temel bilimler bölümü ar gör temsilciği
B25: 5. İTÜ-DELMAR denizde canlı kalma eğitim merkezi koordinatörlüğü
B26: 6. Pearson Sisteminde görevli (Matematik)
B27: 7. 4.sınıf amiri
A28: Rukiye GÜLMEZ | B28: 1. Liman Komisyonu
B29: 2. Not Komisyonu
B30: 3. Simülatör yardımcıılığı
B31: 4. Staj Komisyonu
B32: 5. ERS I dersini verecek. (Cuma)
A33: Samet BİÇEN | B33: 1. Her Cuma Teknopark görevi | D33: DERS PROGRAMI
B34: 2. Liman Komisyonu | D34: Engine Room Simulator (ERS) I | E34: Çarşamba | F34: 08:30/11:29
B35: 3. Not Komisyonu | D35: Ship Machinery Operation and Maintenance | E35: Çarşamba | F35: 13:30/15:29
D36: Gemi Yardımcı Makineleri II | E36: Perşembe | F36: 08:30/11:29
D37: Gemi Mak. Operasyon&Bakımı | E37: Perşembe | F37: 13:30/15:29
D38: Gemi Mak. Operasyon&Bakımı | E38: Perşembe | F38: 15:30/17:29
A39: Y.Tarık MUTLU | B39: 1. Not Komisyonu | D39: DERS PROGRAMI
B40: 2. Liman Komisyonu | D40: YTÜ | E40: Salı | F40: Tüm Gün | G40: Güz Dönemi
...

Sheet Begüm DOGANAY
A1: Sayı | B1: Görev | C1: Çalışılan saat | D1: Tarih | E1: Puan | I1: DAİMİ GÖREVLER
A2: 1 | B2: Toplantı (MÜDEK ) | C2: 5 | D2: 45859 | E2: 4 | F2: =SUM(E2:E16) -> 82 | I2: 1 | J2: Kalite komisyonu: ABET tüm evrakları düzenleme, raporlama
A3: 2 | B3: MÜDEK ders katalogları hazırlama | D3: 45859 | E3: 2 | I3: 2 | J3: İTÜ DF Ar.Gör temsilciliği
A4: 3 | B4: MÜDEK ders katalogları hazırlama | D4: 45860 | E4: 2 | I4: 3 | J4: İTÜ DF Makine Ar.Gör.Temsilciliği
A5: 4 | B5: Toplantı (MÜDEK ) | C5: 5 | D5: 45861 | E5: 4 | I5: 4 | J5: MÜDEK
A6: 5 | B6: Tanıtım günleri (Fakülte-Haftaiçi) | C6: TÜM GÜN | D6: 45862 | E6: 6 | I6: 5 | J6: Tasarım Projesi Komisyonu | K6: Düzenli olarak toplantılar yapılacaktır.
A7: 6 | B7: Toplantı (MÜDEK ) | C7: 5 | D7: 45862 | E7: 4 | I7: 6 | J7: GMİM YL Komisyonu | K7: Her hafta toplantı yapılmaktadır.
A8: 7 | B8: MÜDEK ders katalogları hazırlama | D8: 45863 | E8: 2
A9: 8 | B9: Tanıtım günleri (Ayazağa-Haftasonu) | C9: TÜM GÜN | D9: 45864 | E9: 10
A10: 9 | B10: Tanıtım günleri (Ayazağa-Haftasonu) | C10: TÜM GÜN | D10: 45865 | E10: 10 | I10: * | J10: 4-5 Aralık 2025 izinli
A11: 10 | B11: Tanıtım günleri (Fakülte-Haftaiçi) | C11: TÜM GÜN | D11: 45866 | E11: 6 | I11: * | J11: 10 Aralık 2025 15:30 Bölüm kuruluna herkes geldiği için kimseye puan verilmedi.
A12: 11 | B12: Toplantı (MÜDEK ) | C12: 2 | D12: 45867 | E12: 2
A13: 12 | B13: Tanıtım günleri (Ayazağa-Haftaiçi) | C13: TÜM GÜN | D13: 45869 | E13: 8
A14: 13 | B14: Tanıtım günleri (Fakülte-Haftasonu) | C14: TÜM GÜN | D14: 45872 | E14: 8
A15: 14 | B15: MÜDEK ders katalogları hazırlama | C15: 6 adet | D15: 45872 | E15: 12
A16: 15 | B16: MÜDEK öz değerlendirme formu oluşturma | C16: 2 | D16: 45872 | E16: 2
A17: 16 | B17: Not Komisyonu | C17: 4 | D17: 45931 | E17: 3 | F17: =SUM(E17:E56) -> 136
A18: 17 | B18: NATO ön hazırlık | C18: TÜM GÜN | D18: 45942 | E18: 4
A19: 18 | B19: NATO 13-17 Ekim görevlendirme | C19: TÜM GÜN | D19: 13-17 Ekim 2025 | E19: 20
A20: 19 | B20: Toplantı (Bölüm Kurulu) | C20: 4 saat | D20: 45951 | E20: 3
A21: 20 | B21: ERS 1 (İsmail Çiçek yerine) | D21: 45953 | E21: 2
A22: 21 | B22: Toplantı (GMİM-Lisansüstü) | C22: 1.5 saat | D22: 45966 | E22: 1
A23: 22 | B23: Tuzla haftaiçi 1 sınav (Gemi Elektrotekniği) | C23: 1 saat | D23: 45971 | E23: 1
A24: 23 | B24: Tuzla haftaiçi 1 sınav (Atölye) | C24: 18:00-19:00 | D24: 45971 | E24: 2
A25: 24 | B25: Toplantı (GMİM-Lisansüstü) | C25: 2 saat | D25: 45972 | E25: 2
A26: 25 | B26: Toplantı (Tasarım Projeleri) (1800'a kadar) | C26: 14:00-18:00 | D26: 45972 | E26: 4
A27: 26 | B27: Tasarım Projeleri poster hazırlama (1 adet) | C27: 4-5 saat | D27: 45973 | E27: 3
A28: 27 | B28: Tasarım Projeleri poster hazırlama (1 adet) | C28: 4-5 saat | D28: 45974 | E28: 3
A29: 28 | B29: Tasarım Projeleri poster hazırlama (2 adet) | C29: TÜM GÜN | D29: 45977 | E29: 6
A30: 29 | B30: Toplantı (GMİM-Lisansüstü) | C30: 2 saat | D30: 45979 | E30: 2
A31: 30 | B31: Tuzla haftasonu 1 sınav (KIM101) | C31: 2 saat | D31: 45990 | E31: 3
A32: 31 | B32: GMIM-YL Ders Katalog Formu Hazırlama | C32: 1 adet | D32: 45980 | E32: 2
A33: 32 | B33: Tasarım Projeleri poster revize | D33: 45999 | E33: 1
A34: 33 | B34: Toplantı (GMİM-Lisansüstü) | C34: 2 saat | D34: 45993 | E34: 2
A35: 34 | B35: Toplantı (GMİM-Lisansüstü) | C35: 1 saat | D35: 46000 | E35: 1
A36: 35 | B36: GMIM-YL Ders Katalog Formu Hazırlama | C36: 1 adet | D36: 46000 | E36: 2
A37: 36 | B37: Toplantı (GMİM-Lisansüstü) | C37: 2 saat | D37: 46007 | E37: 2
A38: 37 | B38: Toplantı (Bölüm Kurulu) | C38: 15:30-18:00 | D38: 46008 | E38: 2
A39: 38 | B39: Toplantı (GMİM-Lisansüstü) | C39: 10:00-12:15 | D39: 46014 | E39: 2
A40: 39 | B40: Toplantı (GMİM-Lisansüstü) tutanak hazırlama | C40: 8 adet | D40: tüm dönem | E40: 2
...

Sheet Fatih NACAR
A1: Sayı | B1: Görev | C1: Çalışılan saat | D1: Tarih | E1: Puan | I1: DAİMİ GÖREVLERİ
A2: 1 | B2: Maslak Mezuniyet | C2: 8 saat | D2: 45850 | E2: 5 | F2: =SUM(E2:E14) -> 70 | K2: Görevi
A3: 2 | B3: Staj başvuru ve kabul işleri | C3: 2 saat | D3: 45859 | E3: 1 | I3: 1 | J3: Kalite Komisyonu | K3: ABET evrakları düzenlemesinde yardımcı olmaktadır.
A4: 3 | B4: MÜDEK ders katalogları hazırlama | D4: 45859 | E4: 2 | I4: 2 | J4: Staj Komisyonu | K4: Eğitim gemisine öğrenci seçimi gemiyle okul arasındaki iletişim
A5: 4 | B5: MÜDEK ders katalogları hazırlama | D5: 45860 | E5: 2 | I5: 3 | J5: 3.Sınıf amiri | K5: 3.sınıf öğrencileri ile ilgilenmekte.
A6: 5 | B6: Toplantı (MÜDEK ) | C6: 5 | D6: 45861 | E6: 4 | I6: 4 | J6: Tasarım Projesi Komisyonu | K6: Düzenli olarak toplantılar yapılacaktır.
A7: 6 | B7: Tanıtım günleri (Fakülte-Haftaiçi) | C7: TÜM GÜN | D7: 45862 | E7: 6 | I7: 5 | J7: GMİM YL KOMİSYONU | K7: Her hafta toplantı yapılmaktadır.
A8: 7 | B8: Tanıtım günleri (Fakülte-Haftaiçi) | C8: 8 saat | D8: 45863 | E8: 6 | I8: 6 | J8: Atölye (her pazartesi) | K8: Atölye dersini asiste etmektedir.
A9: 8 | B9: Tanıtım günleri (Fakülte-Haftaiçi) | C9: 8 saat | D9: 45867 | E9: 6 | I9: 7 | J9: Malzeme Bilgisi | K9: Salı 13:30
A10: 9 | B10: Tanıtım günleri (Fakülte-Haftaiçi) | C10: 8 saat | D10: 45868 | E10: 6
A11: 10 | B11: Tanıtım günleri (Ayazağa-Haftaiçi) | C11: 8 saat | D11: 45870 | E11: 8 | I11: * | J11: 10 Aralık 2025 15:30 Bölüm kuruluna herkes geldiği için kimseye puan verilmedi.
A12: 11 | B12: Tanıtım günleri (Ayazağa-Haftasonu) | C12: 8 saat | D12: 45871 | E12: 10 | I12: *
A13: 12 | B13: Tanıtım günleri (Ayazağa-Haftasonu) | C13: 8 saat | D13: 45872 | E13: 10
A14: 13 | B14: Fizik sınavı (Maslak) | C14: 2 saat | D14: 45887 | E14: 4
A15: 14 | B15: Sisteme katalog çıktı girdisi | C15: 2 saat | D15: 45916 | E15: 1 | F15: =SUM(E15:E57) -> 115
A16: 15 | B16: Sisteme katalog çıktı girdisi | C16: 1 saat | D16: 45917 | E16: 1
A17: 16 | B17: Not Komisyonu | C17: 2 saat | D17: 45925 | E17: 2
A18: 17 | B18: Sisteme SUNY katalog yüklemesi | C18: 1 saat | D18: 45936 | E18: 1
A19: 18 | B19: Sisteme SUNY katalog yüklemesi | C19: 1 saat | D19: 45937 | E19: 1
A20: 19 | B20: Sisteme SUNY katalog yüklemesi | C20: 1 saat | D20: 45938 | E20: 1
A21: 20 | B21: Sisteme SUNY katalog yüklemesi | C21: 1 saat | D21: 45939 | E21: 1
A22: 21 | B22: NATO ön hazırlık | C22: TÜM GÜN | D22: 45941 | E22: 4
A23: 22 | B23: NATO 13-17 Ekim görevlendirme | C23: TÜM GÜN | D23: 13-17 Ekim 2025 | E23: 20
A24: 23 | B24: Toplantı (Bölüm Kurulu) | C24: 4 saat | D24: 45951 | E24: 3
A25: 24 | B25: CMP 111 (Çağlar Karatuğ yerine) | C25: <1 saat | D25: 45951 | E25: 1
A26: 25 | B26: Not Komisyonu evrakları (ABET) | C26: 1 saat | D26: 45954 | E26: 1
A27: 26 | B27: Liman Komisyonu | C27: <1 saat | D27: 45964 | E27: 1
A28: 27 | B28: Kariyer Günleri (yoklama) | C28: 1 Hafta | D28: 3-7 Ekim 2025 | E28: 5
A29: 28 | B29: Toplantı (GMİM-Lisansüstü) | C29: 1.5 saat | D29: 45966 | E29: 1
A30: 29 | B30: Toplantı (GMİM-Lisansüstü) | C30: 2 saat | D30: 45972 | E30: 2
A31: 30 | B31: Toplantı (Tasarım Projeleri) (1800'a kadar) | C31: 4 saat | D31: 45972 | E31: 4
A32: 31 | B32: Malzeme Bilgisi | C32: 1 ders | D32: GÜZ DÖNEMİ | E32: 10
A33: 32 | B33: Atölye | C33: 3 ders | D33: YARI DÖNEM | E33: 15
A34: 33 | B34: Uzun staj için öğrenci beyanlarının kontrolü | C34: 1 saat | D34: 45973 | E34: 1
A35: 34 | B35: Ders yedekleme (Tek seferlik)-Samet Biçen yerine | C35: 1 ders | D35: 45974 | E35: 1
A36: 35 | B36: Tuzla haftaiçi 1 sınav (Kariyer günleri)-mesai dışı | C36: 1 saat | D36: 45974 | E36: 2
A37: 36 | B37: Seyit Onbaşı gemisi staj kabul esaslarının belirlenmesi | C37: 13:30-15:00 | D37: 45979 | E37: 1
A38: 37 | B38: Seyit Onbaşı gemisi staj kabul esaslarının belirlenmesi | C38: 13:30-15:00 | D38: 45980 | E38: 1
A39: 38 | B39: Tuzla haftasonu 1 sınav (FIZ101) | C39: 2 saat | D39: 45991 | E39: 3
A40: 39 | B40: Tuzla haftaiçi 3 sınav (Atölye-Çağlar Karatuğ) | C40: 3 sınav | D40: 45992 | E40: 3
...

Sheet Y.Tarık MUTLU
A1: Sayı | B1: Görev | C1: Çalışılan saat | D1: Tarih | E1: Puan | I1: Ders Programı | N1: DAİMİ GÖREVLER
A2: 1 | B2: Fakülte Gezisi (2 Saat üzeri) | C2: TÜM GÜN | D2: 45848 | E2: 3 | F2: =SUM(E2:E13) -> 71 | I2: Ders adı | J2: Gün | K2: Saat | L2: Aralığı | N2: 1 | O2: Not Komisyonu
A3: 2 | B3: Mezuniyet Maslak | C3: 15:00-23:00 | D3: 45850 | E3: 5 | I3: YTÜ | J3: Salı | K3: Tüm Gün | L3: Güz Dönemi | N3: 2 | O3: Liman Komisyonu
A4: 3 | B4: Tanıtım günleri (Ayazağa-Haftaiçi) | C4: TÜM GÜN | D4: 45862 | E4: 8 | I4: Online (Tuzla Ofisten) | J4: Çarşamba | K4: 13:00-17:00 | L4: 8 Ekim - 29 Kasım | N4: 3 | O4: Makine 1. Sınıflar Amiri
A5: 4 | B5: Ders Değerlendirme Anketi Rapor Hazırlama | C5: 1 Mesai Günü | D5: 45863 | E5: 2 | I5: YTÜ | J5: Perşembe | K5: Tüm Gün | L5: Güz Dönemi | N5: 4 | O5: Tez Dağıtım
A6: 5 | B6: Tanıtım günleri (Fakülte-Haftasonu) | C6: TÜM GÜN | D6: 45864 | E6: 8 | I6: Online (Tuzla Ofisten) | J6: Cuma | K6: 13:00-17:00 | L6: 5 Aralık - 2 Ocak
A7: 6 | B7: Tanıtım günleri (Fakülte-Haftaiçi) | C7: TÜM GÜN | D7: 45866 | E7: 6 | I7: Online (Tuzla Ofisten) | J7: Cuma | K7: 13:00-17:00 | L7: 6 Şubat - 8 Mayıs
A8: 7 | B8: Tanıtım günleri (Ayazağa-Haftaiçi) | C8: TÜM GÜN | D8: 45868 | E8: 8
A9: 8 | B9: Tanıtım günleri (Fakülte-Haftaiçi) | C9: TÜM GÜN | D9: 45870 | E9: 6
A10: 9 | B10: Tanıtım günleri (Fakülte-Haftasonu) | C10: TÜM GÜN | D10: 45871 | E10: 8 | I10: * | J10: 10 Aralık 2025 15:30 Bölüm kuruluna herkes geldiği için kimseye puan verilmedi.
A11: 10 | B11: Tanıtım günleri (Ayazağa-Haftasonu) | C11: TÜM GÜN | D11: 45872 | E11: 10
A12: 11 | B12: Maslak haftasonu 1 sınav | C12: 2 SAAT | D12: 45872 | E12: 3
A13: 12 | B13: Maslak haftaiçi 1 sınav | C13: 2 SAAT | D13: 45887 | E13: 4
A14: 13 | B14: Ders Programı İşleri | C14: 11:00-16:00 | D14: 45901 | E14: 3 | F14: =SUM(E14:E131) -> 203
A15: 14 | B15: Ders Programı İşleri | C15: 10:00-15:00 | D15: 45902 | E15: 3
A16: 15 | B16: Ders Programı İşleri | C16: 09:30-17:00 | D16: 45904 | E16: 4
A17: 16 | B17: Ders Programı İşleri | C17: 13:00-15:30 | D17: 45908 | E17: 1
A18: 17 | B18: Ders Programı İşleri | C18: 14:00-17:00 | D18: 45910 | E18: 1
A19: 18 | B19: Not Komisyonu | C19: 09:00-12:00 | D19: 45925 | E19: 2
A20: 19 | B20: Ders Programı İşleri | C20: 09:00-17:00 | D20: 45926 | E20: 4
A21: 20 | B21: Ders Programı İşleri | C21: 14:00-17:00 | D21: 45928 | E21: 4
A22: 22 | B22: Ders Programı İşleri | C22: 20:30-22:00 | D22: 45930 | E22: 2
A23: 23 | B23: Not Komisyonu | C23: 10:00-14:00 | D23: 45931 | E23: 3
A24: 25 | B24: Ders Programı İşleri | C24: 19:00-20:00 | D24: 45931 | E24: 1
A25: 27 | B25: Liman Komisyonu | C25: 10:00-11:00 | D25: 45933 | E25: 1
A26: 28 | B26: Burs Komisyonu Fakülte Burs Formu Hazırlama | C26: 3 SAAT | D26: 45933 | E26: 2
... A34: 37 | B34: Ders Programı İşleri | C34: 22:45-00:15 | D34: 45942 | E34: 2
A35: 38 | B35: NATO 13-17 Ekim görevlendirme | C35: TÜM GÜN | D35: 3 GÜN | E35: 12
A36: 39 | B36: Havuz dersleri sınavları için derslik planlama | C36: 2 SAAT | D36: 45950 | E36: 1
A37: 40 | B37: Liman Komisyonu | C37: <1 saat | D37: 45964 | E37: 1
A38: 41 | B38: Tuzla haftaiçi 1 sınav (Emre Hoca) | C38: 1 saat | D38: 45979 | E38: 1
A39: 42 | B39: Toplantı (Burs Komisyonu) | C39: 11:00 - 12:30 | D39: 45980 | E39: 1
A40: 43 | B40: GMİM Stajlarının akış şeması oluşturma | C40: 10:00 - 12:00 | D40: 45987 | E40: 2
A41: 44 | B41: GMİM atölye stajı akış diyagramı oluşturma | C41: 20:00 - 22:15 | D41: 45987 | E41: 3
A42: 45 | B42: Toplantı (Staj Komisyonu) | C42: 15:30 - 16:30 | D42: 45987 | E42: 1
A43: 46 | B43: Tuzla haftasonu 1 sınav (KIM101) | C43: 2 saat | D43: 45990 | E43: 3
A44: 47 | B44: Tuzla haftasonu 1 sınav (FIZ101) | C44: 2 saat | D44: 45991 | E44: 3
A45: 48 | B45: Tuzla haftaiçi 1 sınav (Yalçın Durmuşoğlu) | C45: 12:00-13:30 | D45: 45992 | E45: 1
A46: 49 | B46: Hurdaya gidecek malzemelerin sayımı ve tespiti | C46: 13:30-14:00 | D46: 45994 | E46: 1
A47: 50 | B47: 2026 Bahar ders programı işleri | C47: 08:00-11:00 | D47: 46003 | E47: 2
...

Sheet Merve GÜL ÇIVGIN
A1: Sayı | B1: Görev | C1: Çalışılan saat | D1: Tarih | E1: Puan | I1: DAİMİ GÖREVLER
A2: 1 | B2: Tanıtım günleri (Fakülte-Haftaiçi) | C2: tüm gün | D2: 45862 | E2: 6 | F2: =SUM(E2:E9) -> 51 | I2: 1 | J2: Burs Komisyonu
A3: 2 | B3: Tanıtım günleri (Ayazağa-Haftaiçi) | C3: tüm gün | D3: 45863 | E3: 8 | I3: 2 | J3: Dekanlık üzerinden yapılan protokollere tesis ayarlama ve eğitim planlama
A4: 3 | B4: Ders Değerlendirme Anketi Rapor Hazırlama | C4: 1 Mesai Günü | D4: 45863 | E4: 2 | I4: 3 | J4: Simülatör sorumlusu
A5: 4 | B5: Tanıtım günleri (Ayazağa-Haftaiçi) | C5: tüm gün | D5: 45867 | E5: 8 | I5: 4 | J5: SEM
A6: 5 | B6: Tanıtım günleri (Fakülte-Haftaiçi) | C6: tüm gün | D6: 45868 | E6: 6 | I6: 5 | J6: GMİM YL Komisyonu | K6: Her hafta toplantı yapılmaktadır.
A7: 6 | B7: Tanıtım günleri (Fakülte-Haftaiçi) | C7: tüm gün | D7: 45869 | E7: 6
A8: 7 | B8: Fakülte gezdirme (Çinliler) | C8: 4 saat | D8: 45873 | E8: 3 | I8: * | J8: 17-18 Aralık 2025 izinli
A9: 8 | B9: Fakülte tanıtımı (random) | C9: 2 gün | D9: 5-6 Ağustos 2025 | E9: 12
A10: 9 | B10: Bakanlık denet günü | D10: 45925 | E10: 2 | F10: =SUM(E10:E77) -> 122 | I10: * | J10: 10 Aralık 2025 15:30 Bölüm kuruluna herkes geldiği için kimseye puan verilmedi.
A11: 10 | B11: NATO VIP Kayıt ve iletişim | C11: 3 saat | D11: 45928 | E11: 3 | I11: * | J11: 6 Nisan'dan 9 Nisan'a kadar izinli
A12: 11 | B12: NATO Fakülte Hocalarının Kaydı | C12: 4 saat | D12: 45929 | E12: 2 | I12: * | J12: 19 Mayıs 2026 haftası izinli
A13: 12 | B13: NATO Öğrencilerin Kaydı | C13: 4 saat | D13: 45932 | E13: 2
A14: 13 | B14: NATO basın görevlendirmesi | C14: 4 gün | D14: 45945 | E14: 16
A15: 14 | B15: Simülatör tanıtımı | D15: 45946 | E15: 1
A16: 15 | B16: Toplantı (Bölüm Kurulu) | C16: 4 saat | D16: 45951 | E16: 3
A17: 16 | B17: Toplantı (GMİM-Lisansüstü) | C17: 1.5 saat | D17: 45966 | E17: 1
A18: 17 | B18: Toplantı (GMİM-Lisansüstü) | C18: 2 saat | D18: 45972 | E18: 2
A19: 18 | B19: Toplantı (Burs Komisyonu) | C19: 1 saat | D19: 45972 | E19: 1
A20: 19 | B20: Tuzla haftaiçi 1 sınav (Çağlar Hoca) | C20: 1 saat | D20: 45973 | E20: 1
A21: 20 | B21: Tuzla haftaiçi 1 sınav (Çağlar Hoca) | C21: 1 saat | D21: 45974 | E21: 1
A22: 21 | B22: Toplantı (GMİM-Lisansüstü) | C22: 2 saat | D22: 45979 | E22: 2
A23: 22 | B23: Toplantı (Burs Komisyonu) | C23: 11:00 - 12:30 | D23: 45980 | E23: 1
A24: 23 | B24: Toplantı (GMİM-Lisansüstü) | C24: 2 saat | D24: 45986 | E24: 2
A25: 24 | B25: Tuzla haftasonu 1 sınav (MAT103) | C25: 2 saat | D25: 45983 | E25: 3
A26: 25 | B26: Tuzla haftasonu 1 sınav (FIZ101) | C26: 2 saat | D26: 45991 | E26: 3
A27: 26 | B27: Toplantı (GMİM-Lisansüstü) | C27: 2 saat | D27: 45993 | E27: 2
... A53: 52 | B53: Toplantı (IMHFC) | C53: 14:00-15:00 | D53: 46072 | E53: 1
A54: 53 | B54: İç Tetkik | C54: 1 adet | E54: 1
A55: 54 | B55: Bakanlık Deneti | C55: 0930-1200 | D55: 46073 | E55: 2
A56: 55 | B56: Toplantı (IMHFC) | C56: 11:00-12:00 | D56: 46077 | E56: 1
A57: 56 | B57: Toplantı (Bölüm Kurulu) | C57: 15:30-16:15 | D57: 46078 | E57: 1
A58: 57 | B58: IMHFC arayüz hazırlığı | C58: 3 saat | D58: 46078 | E58: 3
A59: 58 | B59: Toplantı (IMHFC) | C59: 11:00-12:00 | D59: 46083 | E59: 1
A60: 59 | B60: Toplantı (Bölüm Kurulu) | C60: 0930-1230 | D60: 46087 | E60: 2
A61: 60 | B61: IMHFC revizyon | C61: 1 saat | D61: 46103 | E61: 2
A62: 61 | B62: Tuzla haftaiçi 1 sınav (Yalçın Durmuşoğku) | C62: 1200-1300 | D62: 46105 | E62: 1
A63: 62 | B63: Toplantı (IMHFC) | C63: 45dk | D63: 46105 | E63: 1
A64: 63 | B64: Toplantı (IMHFC)-(Fatih ve Esma Hoca ile birlikte) | C64: 1 saat | D64: 46105 | E64: 1
A65: 64 | B65: Ders yedekleme (Tek seferlik)-Cengiz Deniz | C65: 1230-1530 | D65: 46106 | E65: 2
...

Sheet Sinan COŞKUN
A1: Sayı | B1: Görev | C1: Çalışılan saat | D1: Tarih | E1: Puan | I1: Asiste Edilen Ders Programı
A2: 1 | B2: NATO Kapıda karşılama | C2: Tüm Gün | D2: 45944 | E2: 4 | I2: Ders kodu | J2: Ders adı | K2: Gün | L2: Saat
A3: 2 | B3: NATO Kapıda karşılama | C3: Tüm Gün | D3: 45946 | E3: 4 | I3: GMI 324E | J3: Ship Machinery Operation and Maintenance | K3: Çarşamba | L3: 13:30/15:29
A4: 3 | B4: Fakülte Gezisi (1-2 saat) | C4: 1 saat | D4: 45952 | E4: 2 | I4: GMI 324 | J4: Gemi Mak. Operasyon&Bakımı | K4: Perşembe | L4: 13:30/15:29
A5: 4 | B5: Kariyer Günleri (yoklama) | C5: 1 saat | D5: 45964 | E5: 1 | I5: GMI 324 | J5: Gemi Mak. Operasyon&Bakımı | K5: Perşembe | L5: 15:30/17:29
A6: 5 | B6: Tuzla haftaiçi 1 sınav (Atölye) | C6: 18.00 | D6: 45971 | E6: 2
A7: 6 | B7: GMI 324 ders asiste etme | C7: 3 ders | D7: YARI DÖNEM | E7: 15
A8: 7 | B8: Tuzla haftaiçi 1 sınav (Emre Kahramanoğlu) | C8: 1 saat | D8: 45979 | E8: 1 | I8: * | J8: 10 Aralık 2025 15:30 Bölüm kuruluna herkes geldiği için kimseye puan verilmedi.
A9: 8 | B9: Tuzla haftasonu 1 sınav (MAT103) | C9: 2 saat | D9: 45983 | E9: 3 | I9: * | J9: 4 Nisan Ayazağa'da
A10: 9 | B10: HUK213 ara sınavı (Ayazağa) | D10: 45985 | E10: 4
A11: 10 | B11: Tuzla haftasonu 1 sınav (KIM101) | C11: 2 saat | D11: 45990 | E11: 3
A12: 11 | B12: Tuzla haftasonu 1 sınav (FIZ101) | C12: 2 saat | D12: 45991 | E12: 3
A13: 12 | B13: Tuzla haftaiçi 1 sınav (Cengiz Deniz-Burak Zincir) 16:00 | C13: <1 saat | D13: 45994 | E13: 1
A14: 13 | B14: Fakülte Gezisi (1-2 saat) | C14: 1 saat | D14: 46001 | E14: 2
A15: 14 | B15: Ders yedekleme (Tek seferlik) | C15: 3 ders | D15: 46006 | E15: 6
A16: 15 | B16: Tuzla haftaiçi 1 sınav (Çağlar Karatuğ) | C16: 0.52083333 | D16: 46008 | E16: 1
A17: 16 | B17: Toplantı (Bölüm Kurulu) | C17: 15:30-18:00 | D17: 17 Aralık 2025 Çarşamba | E17: 2
A18: 17 | B18: Simülatör Anlatımı | C18: <1 saat | D18: 46009 | E18: 1
A19: 18 | B19: Fakülte Gezisi (1-2 saat) | C19: 14:00-16:00 | D19: 46013 | E19: 2
A20: 19 | B20: Simülatör Anlatımı | C20: 14:00-14:30 | D20: 46015 | E20: 1
A21: 20 | B21: Tuzla haftaiçi 1 sınav (Burak Zincir) | C21: 15:00-15:30 | D21: 46015 | E21: 1
A22: 21 | B22: Tuzla haftaiçi 1 sınav (Samet Biçen) | C22: 15:45-16:15 | D22: 46015 | E22: 1
A23: 22 | B23: Tuzla haftaiçi 1 sınav (Samet Biçen) | C23: 12:00-14:00 | D23: 46027 | E23: 1
A24: 23 | B24: Tuzla haftaiçi 1 sınav (Seçkin Mengeçin) | C24: 15:00-17:00 | D24: 46027 | E24: 1
A25: 24 | B25: Tuzla haftaiçi 1 sınav (Tayfun Uyanık) | C25: 15:00-17:00 | D25: 46030 | E25: 1
A26: 25 | B26: Tuzla haftasonu 1 sınav (Sabire Cömert) | C26: 09:00-11:00 | D26: 46032 | E26: 2
A27: 26 | B27: Tuzla haftasonu 1 sınav (Kemal Demirel) | C27: 09:00-11:00 | D27: 46033 | E27: 2
A28: 27 | B28: Tuzla haftasonu 1 sınav (Hakan Demirel) | C28: 12:00-14:00 | D28: 46033 | E28: 2
A29: 28 | B29: Tuzla haftaiçi 1 sınav (KIM) | C29: 12:00-14:00 | D29: 46034 | E29: 2
... A38: 37 | B38: Toplantı (Staj Komisyonu) | C38: 11:00-12:55 | D38: 46042 | E38: 2
A39: 38 | B39: Fakülte Gezisi (1-2 saat) | D39: 46066 | E39: 2
A40: 39 | B40: Fakülte Gezisi (1-2 saat) | C40: 10:00-12:00 | D40: 46073 | E40: 2
A41: 40 | B41: GMI 320E-Ship Construction and Stability | C41: Çarşamba | D41: BAHAR DÖNEMİ | E41: 20
A42: 41 | B42: İç Tetkik | C42: 1 adet | E42: 1
A43: 42 | B43: Liman Komisyonu | C43: 1 saat | D43: 45706 | E43: 1
A44: 43 | B44: Toplantı (Bölüm Kurulu) | C44: 0930-1230 | D44: 46087 | E44: 2
A45: 44 | B45: Sertifika toplama düzeneleme | E45: 3
A46: 45 | B46: GMI210-Titreşimin Temelleri | C46: Salı | D46: BAHAR DÖNEMİ | E46: 20
A47: 46 | B47: Tuzla haftaiçi 1 sınav (Veysi Başhan) | C47: 1030 | D47: 46112 | E47: 1
A48: 47 | B48: Ders yedekleme (Tek seferlik)-Hakan Demirel | E48: 2
...

Sheet Rukiye GÜLMEZ
A1: Sayı | B1: Görev | C1: Çalışılan saat | D1: Tarih | E1: Puan | I1: DAİMİ GÖREVLER
A2: 1 | B2: Simülatör Anlatımı | C2: <1 saat | D2: 45848 | E2: 1 | F2: =SUM(E2:E9) -> 48 | I2: 1 | J2: Liman ve Not Komisyonu
A3: 2 | B3: Fakülte Gezisi (2 Saat üzeri) | C3: >2 saat | D3: 45849 | E3: 3 | I3: 2 | J3: Simülatör yardımcısı
A4: 3 | B4: Tanıtım günleri (Fakülte-Haftaiçi) | C4: TÜM GÜN | D4: 45863 | E4: 6 | I4: 3 | J4: ERS I dersini verecek. (Her Cuma)
A5: 4 | B5: Tanıtım günleri (Fakülte-Haftasonu) | C5: TÜM GÜN | D5: 45865 | E5: 8 | I5: 4 | J5: Staj komisyonu
A6: 5 | B6: Tanıtım günleri (Ayazağa-Haftaiçi) | C6: TÜM GÜN | D6: 45866 | E6: 8
A7: 6 | B7: Tanıtım günleri (Fakülte-Haftaiçi) | C7: TÜM GÜN | D7: 45867 | E7: 6 | I7: * | J7: 20-23 Ekim 2025 izinli
A8: 7 | B8: Tanıtım günleri (Fakülte-Haftaiçi) | C8: TÜM GÜN | D8: 45869 | E8: 6 | I8: * | J8: 1 Aralık 2025 Salı günleri kontrole gidiyor
A9: 8 | B9: Tanıtım günleri (Ayazağa-Haftasonu) | C9: TÜM GÜN | D9: 45871 | E9: 10 | I9: * | J9: 5 Ocak 2026 izinli
A10: 9 | B10: Not Komisyonu | C10: 2 saat | D10: 45925 | E10: 2 | F10: =SUM(E10:E87) -> 126
A11: 10 | B11: Not Komisyonu | C11: 4 saat | D11: 45931 | E11: 3
A12: 11 | B12: ERS I | C12: 1 ders | D12: GÜZ DÖNEMİ | E12: 20
A13: 12 | B13: DUM 461E, DUM 505, MMD 311E (Fırat Bolat yerine) | C13: 3 ders | D13: 45944 | E13: 6
A14: 13 | B14: Tuzla haftaiçi 1 sınav (Stabilite-Emre Kahramanoğlu) | C14: 1830 | D14: 45979 | E14: 2
A15: 14 | B15: Tuzla haftasonu 1 sınav (MAT103) | C15: 2 saat | D15: 45983 | E15: 3
A16: 15 | B16: Tuzla haftaiçi 1 sınav (MEK205E-Zuhal Er) | C16: 0.375 | D16: 45986 | E16: 1 | I16: * | J16: 10 Aralık 2025 15:30 Bölüm kuruluna herkes geldiği için kimseye puan verilmedi.
A17: 16 | B17: Tuzla haftaiçi 1 sınav (Buhar kazanları-Veysi Başhan) | C17: 0.52083333 | D17: 45986 | E17: 1 | I17: * | J17: İç Tetkik yapmadı.
A18: 17 | B18: Tuzla haftaiçi 1 sınav (Ref and HVAC-Veysi Başhan) | C18: 15:30-18:00 | D18: 45986 | E18: 2 | I18: * | J18: 25.03.2026 Liman komisyonuna katılmadı.
A19: 18 | B19: Toplantı (Staj Komisyonu) | C19: 15:30 - 16:30 | D19: 45987 | E19: 1 | I19: * | J19: 31.03.2026 Ayazağa'da
A20: 19 | B20: Tuzla haftasonu 1 sınav (FIZ 101) | C20: 2 saat | D20: 45991 | E20: 3 | I20: * | J20: 02.04.2026 ders asiste etmeyi kabul etmedi
A21: 20 | B21: Tuzla haftaiçi 1 sınav (Burak Zincir) | C21: 1 saat | D21: 45992 | E21: 1 | I21: * | J21: 06.04.2026 Okul gezisine görevlendirilmişti gitmemiş.
A22: 21 | B22: Tuzla haftaiçi 1 sınav (Sabire Cömert) | C22: 0.72916667 | D22: 45994 | E22: 2 | I22: * | J22: 22 Nisan'da izin alacakmış gözetmenliği reddetti.
A23: 22 | B23: Tuzla haftaiçi 1 sınav (Yeterlik Sınavı) | D23: 46007 | E23: 4 | I23: * | J23: 19 Nisan ATA sınavına gelmeyecek Tarık ile değiştirdi.
A24: 23 | B24: Lisans bitirme tezi (1 adet) | C24: 1 adet | D24: 46008 | E24: 2 | I24: * | J24: 25 Nisan Fizik sınavına gelmeyecek, Sivas'a gidecekmiş
A25: 24 | B25: Tuzla haftaiçi 1 sınav (Burak Zincir) | C25: 0.375 | D25: 46009 | E25: 1 | I25: * | J25: 16.04.2026 Argör toplantısına katılmadı.
A26: 25 | B26: 2025 yılı faaliyet raporu hazırlama | E26: 3 | I26: * | J26: 20.05.2026 Yeterlik sınavına müsait değilim dedi.
A27: 26 | B27: Tuzla haftaiçi 1 sınav (Tayfun Uyanık) | C27: 09:00-11:00 | D27: 46028 | E27: 1
A28: 27 | B28: Tuzla haftaiçi 1 sınav (Yalçın Durmuşoğlu) | C28: 12:00-14:00 | D28: 46028 | E28: 1
A29: 28 | B29: Tuzla haftaiçi 1 sınav (Emre Kahramanoğlu) | C29: 15:00-17:00 | D29: 46028 | E29: 1
A30: 29 | B30: Tuzla haftaiçi 1 sınav (FIZ101) | C30: 09:00-11:00 | D30: 46031 | E30: 2
A31: 30 | B31: Tuzla haftasonu 1 sınav (Sabire Cömert) | C31: 09:00-11:00 | D31: 46032 | E31: 2
A32: 31 | B32: Tuzla haftasonu 1 sınav (Çağlar Karatuğ) | C32: 09:00-11:00 | D32: 46033 | E32: 2
A33: 32 | B33: Tuzla haftasonu 1 sınav (Hakan Demirel) | C33: 12:00-14:00 | D33: 46033 | E33: 2
A34: 33 | B34: Tuzla haftaiçi 1 sınav (KIM) | C34: 12:00-14:00 | D34: 46034 | E34: 2
A35: 34 | B35: Tuzla haftaiçi 1 sınav (Ata Bilgili) | C35: 15:00-17:00 | D35: 46034 | E35: 1
A36: 35 | B36: Tuzla haftaiçi 1 sınav (MAT) | C36: 09:00-11:00 | D36: 46035 | E36: 2
A37: 36 | B37: Tuzla haftaiçi 1 sınav (Burak Zincir) | C37: 09:00-11:00 | D37: 46036 | E37: 1
A38: 37 | B38: Tuzla haftaiçi 1 sınav (Kadir Çiçek) | C38: 12:00-14:00 | D38: 46036 | E38: 1
... A41: 40 | B41: Staj Bilgilendirme Toplantısı | C41: 18:00-19:00 | D41: 46038 | E41: 2
A42: 41 | B42: Yalçın hoca final hazırlığı | C42: 15:00- 16:00 | D42: 46042
...

Sheet Samet BİÇEN
A1: Sayı | B1: Görev | C1: Çalışılan saat | D1: Tarih | E1: Puan | I1: GÜZ DÖNEMİ Ders Programı
A2: 1 | B2: Tanıtım günleri (Ayazağa-Haftasonu) | C2: TÜM GÜN | D2: 45865 | E2: 10 | I2: Ders kodu | J2: Ders adı | K2: Gün | L2: Saat
A3: 2 | B3: Dr.Ar. Gör Ders verme | C3: 4 ders | D3: GÜZ DÖNEMİ | E3: 80 | I3: GMI 384E | J3: Engine Room Simulator (ERS) I | K3: Çarşamba | L3: 08:30/11:29
A4: 3 | B4: Toplantı (Bölüm Kurulu) | C4: 4 saat | D4: 45951 | E4: 2 | H4: kıbrıs | I4: GMI 324E | J4: Ship Machinery Operation and Maintenance | K4: Çarşamba | L4: 13:30/15:29
A5: 4 | B5: Simülatör Anlatımı | C5: <1 saat | D5: 45952 | E5: 1 | I5: GMI 454 | J5: Gemi Yardımcı Makineleri II | K5: Perşembe | L5: 08:30/11:29
A6: 5 | B6: Tersane grevlendirmesi | C6: TÜM GÜN | E6: 4 | I6: GMI 324 | J6: Gemi Mak. Operasyon&Bakımı | K6: Perşembe | L6: 13:30/15:29
A7: 6 | B7: Kariyer günleri (3-7 Kasım 2025) | C7: TÜM GÜN | D7: 45964 | E7: 20 | I7: GMI 324 | J7: Gemi Mak. Operasyon&Bakımı | K7: Perşembe | L7: 15:30/17:29
A8: 7 | B8: Tuzla haftasonu 1 sınav (MAT103) | C8: 2 saat | D8: 45983 | E8: 3
A9: 8 | B9: Tuzla haftasonu 1 sınav (KIM101) | C9: 2 saat | D9: 45990 | E9: 3 | J9: Her Cuma Teknopark görevi
A10: 9 | B10: Tuzla haftasonu 1 sınav (FIZ101) | C10: 2 saat | D10: 45991 | E10: 3
A11: 10 | B11: Liman Komisyonu | C11: 1 saat | D11: 45995 | E11: 1 | I11: * | J11: 10 Aralık 2025 15:30 Bölüm kuruluna herkes geldiği için kimseye puan verilmedi.
A12: 11 | B12: Tuzla haftaiçi 1 sınav (Emre Kahramanoğlu) | C12: 17:30-19:00 | D12: 45687 | E12: 2
A13: 12 | B13: Tuzla haftaiçi 1 sınav (kendi sınavı) | C13: 12:00-14:00 | D13: 46027 | E13: 1
A14: 13 | B14: Tuzla haftaiçi 1 sınav (Veysi Başhan) | C14: 15:00-17:00 | D14: 46027 | E14: 1 | I14: BAHAR DÖNEMİ Ders Programı
A15: 14 | B15: Tuzla haftaiçi 1 sınav (Tayfun Uyanık) | C15: 09:00-11:00 | D15: 46028 | E15: 1 | I15: Ders kodu | J15: Ders adı | K15: Gün | L15: Saat
A16: 15 | B16: Tuzla haftaiçi 1 sınav (kendi sınavı) | C16: 12:00-14:00 | D16: 46028 | E16: 1 | I16: DUI 405 | J16: Gemi Makineleri | K16: Pazartesi | L16: 1130/1330
A17: 16 | B17: Tuzla haftaiçi 1 sınav (Emre Kahramanoğlu) | C17: 15:00-17:00 | D17: 46028 | E17: 1 | I17: GMI 484E | J17: ERS II | K17: Pazartesi | L17: 1430/1730
A18: 17 | B18: Tuzla haftaiçi 1 sınav (KIM) | C18: 12:00-14:00 | D18: 46034 | E18: 2 | I18: GMI 484E | J18: ERS II | K18: Çarşamba | L18: 0830/1129
A19: 18 | B19: Tuzla haftaiçi 1 sınav (Ata Bilgili) | C19: 15:00-17:00 | D19: 46034 | E19: 1 | I19: GMI 484E | J19: ERS II | K19: Çarşamba | L19: 1230/1530
A20: 19 | B20: Tuzla haftaiçi 1 sınav (MAT103) | C20: 09:00-11:00 | D20: 46035 | E20: 2
A21: 20 | B21: Tuzla haftaiçi 1 sınav (Kadir Çiçek) | C21: 12:00-14:00 | D21: 46036 | E21: 1
A22: 21 | B22: Tuzla haftaiçi 1 sınav (Fırat Bolat) | C22: 15:00-17:00 | D22: 46038 | E22: 1
A23: 22 | B23: Tuzla haftaiçi 1 sınav (Zuhal Er) | C23: 15:00-17:00 | D23: 46039 | E23: 2 | J23: 1 Temmuz Mezuniyet Töreni Koordinatörlüğü
A24: 23 | B24: Tuzla haftasonu 1 sınav (Kemal Demirel) | C24: 09:00-11:00 | D24: 46040 | E24: 2 | J24: Teknopark görevlendirme
A25: 24 | B25: Tuzla haftasonu 1 sınav (Seçkin Mengeçin) | C25: 15:00-17:00 | D25: 46040 | E25: 2 | J25: Erasmus
A26: 25 | B26: Liman Komisyonu | C26: 7 kişi | D26: 46042 | E26: 1
A27: 26 | B27: Dr.Ar. Gör Ders verme | C27: 4 ders | D27: BAHAR DÖNEMİ | E27: 80
A28: 27 | B28: Toplantı (Bölüm Kurulu) | C28: 15:30-17:00 | D28: 46071 | E28: 1 | I28: * | J28: 9 Nisan ArGör toplantısına gelmedi.
A29: 28 | B29: İç Tetkik | D29: 46072 | E29: 1 | I29: * | J29: 25 Nisan Fizik sınavına gelmeyecek, oğlunu dişçiye götürecekmiş
A30: 29 | B30: Staj Esas Güncelleme | C30: TÜM GÜN | D30: 46082 | E30: 3
A31: 30 | B31: Toplantı (Bölüm Kurulu) | C31: 0930-1230 | D31: 46087 | E31: 2
A32: 31 | B32: Fakülte kurum dışına görevlendirme | C32: TÜM GÜN | D32: 46087 | E32: 4
A33: 32 | B33: Toplantı (ArGör) | C33: 1630-1730 | D33: 46121 | E33: 1
A34: 33 | B34: Toplantı (ArGör) | C34: 1330-1430 | D34: 46128 | E34: 1
A35: 34 | B35: Tuzla haftasonu 1 sınav (ATA) | C35: 1430-1630 | D35: 46131
A36: 35
A37: 36 | B37: Tuzla haftaiçi 1 sınav (Yalçın Durmuşoğlu) | C37: 0900-1100 | D37: 46174 | E37: 1
A38: 37 | B38: Tuzla haftaiçi 1 sınav (Tayfun Uyanık) | C38: 1500-1700 | D38: 46174 | E38: 1
A39: 38 | B39: Tuzla haftaiçi 1 sınav (Emre Kahramanoğlu) | C39: 1200-1400 | D39: 46177 | E39: 1
A40: 39 | B40: Tuzla haftaiçi 1 sınav (havuz dersleri)-MAT104 | C40: 0900-1100 | D40: 46178 | E40: 2
...

Sheet Cenk KAYA
A1: Sayı | B1: Görev | C1: Çalışılan saat | D1: Tarih | E1: Puan
A2: 1 | B2: Tuzla haftaiçi 1 sınav (Veysi Başhan) | C2: 1030 | D2: 46154 | E2: 1 | I2: staj gemisi planlama komisyonu
A3: 2 | B3: Tuzla haftaiçi 1 sınav (Yalçın Durmuşoğlu) | C3: 1530-1700 | D3: 46156 | E3: 1
A4: 3 | B4: Tuzla haftaiçi 1 sınav (Samet Biçen) | C4: 1400-1500 | D4: 46155 | E4: 1
A5: 4 | B5: Tuzla haftaiçi 1 sınav (Samet Biçen) | C5: 1530-1630 | D5: 46155 | E5: 1 | I5: Mayıs 2025 Yurtdışına gitti
A6: 5 | B6: Tuzla haftaiçi (Yeterlik sınavı) | C6: 0930-1230 | D6: 46162 | E6: 4 | I6: 27 Nisan 2026 yurtdışından geldi
A7: 6 | B7: Ders yedekleme (Tek seferlik)-Ata Bilgili | C7: 2 ders | E7: 4
A8: 7 | B8: Ders yedekleme (Tek seferlik)-Emre Karamanoğlu | C8: 2 ders | E8: 4
A9: 8
A10: 9 | B10: Tuzla haftaiçi 1 sınav (Yalçın Durmuşoğlu) | C10: 0900-1100 | D10: 46174 | E10: 1
A11: 10 | B11: Tuzla haftaiçi 1 sınav (Orhan Gönel) | C11: 1200-1400 | D11: 46174 | E11: 1
A12: 11 | B12: Tuzla haftaiçi 1 sınav (Tayfun Uyanık) | C12: 1500-1700 | D12: 46174 | E12: 1
A13: 12 | B13: Tuzla haftaiçi 1 sınav (ATA I) | C13: 0900-1100 | D13: 46176 | E13: 1 | G13: FİNAL
A14: 13 | B14: Tuzla haftaiçi 1 sınav (ATA I) | C14: 1500-1700 | D14: 46176 | E14: 1 | G14: =SUM(E10:E24) -> 20
A15: 14 | B15: Tuzla haftaiçi 1 sınav (Emre Kahramanoğlu) | C15: 1200-1400 | D15: 46177 | E15: 1
A16: 15 | B16: Tuzla haftaiçi 1 sınav (havuz dersleri)-MAT104 | C16: 0900-1100 | D16: 46178 | E16: 2
A17: 16 | B17: Tuzla haftaiçi 1 sınav (havuz dersleri)-MAT103 | C17: 1500-1700 | D17: 46178 | E17: 2
A18: 17 | B18: Tuzla haftaiçi 1 sınav (Sabire Cömert) | C18: 0900-1100 | D18: 46180 | E18: 2 | I18: 21 Mayıs ve 4 Haziran görev yazma
A19: 18 | B19: Tuzla haftaiçi 1 sınav (Yalçın Durmuşoğlu) | C19: 1500-1700 | D19: 46180 | E19: 2
A20: 19 | B20: Tuzla haftaiçi 1 sınav (Tayfun Uyanık) | C20: 1200-1400 | D20: 46181 | E20: 1
A21: 20 | B21: Tuzla haftaiçi 1 sınav (Ata Bilgili) | C21: 1500-1700 | D21: 46181 | E21: 1
A22: 21 | B22: Tuzla haftaiçi 1 sınav (havuz dersleri)-FIZ102 | C22: 0900-1100 | D22: 46183 | E22: 2
A23: 22 | B23: Tuzla haftaiçi 1 sınav (Emre Kahramanoğlu) | C23: 1500-1700 | D23: 46183 | E23: 1
A24: 23 | B24: Tuzla haftaiçi 1 sınav (Müjgan Özenir) | C24: 0900-1100 | D24: 46185 | E24: 1
A25: 24
A26: 25
A27: 26
A28: 27
A29: 28
A30: 29
A31: 30
A32: 31
A33: 32
A34: 33
A35: 34
A36: 35
... A77: 76
A83: TOPLAM | E83: =SUM(E5:E77) -> 33

Sheet Berkehan İNAL
A1: Sayı | B1: Görev | C1: Çalışılan saat | D1: Tarih | E1: Puan
A2: 1
A3: 2
A4: 3
A5: 4
A6: 5
A7: 6 | H7: 10 EYLÜL 2025 YURTDIŞINA GİDİYOR
A8: 7
A9: 8
A10: 9
A11: 10
A12: 11
A13: 12
A14: 13
A15: 14
A16: 15
A17: 16
A18: 17
A19: 18
... A31: 30

Sheet Muhittin ORHAN
A1: Sayı | B1: Görev | C1: Çalışılan saat | D1: Tarih | E1: Puan | I1: DAİMİ GÖREVLER
A2: 1 | B2: Bakanlık denet günü (itü-delmar eğitim merkezi) | C2: 4 saat | D2: 45925 | E2: 2 | I2: 1 | J2: itü df kalite ve çevre komisyonu
A3: 2 | B3: Bakanlık denet ve seyir/ekipman tanıtımı (itü-delmar eğitim merkezi) | C3: 4 saat | D3: 45926 | E3: 2 | I3: 2 | J3: temel bilimler için kalite koordinatörü
A4: 3 | B4: Temel Bilimler Bölümü - akademik veri toplama ve rapor hazırlığı | C4: 4 saat | D4: 45932 | E4: 2 | I4: 3 | J4: itü df adına yıllık e-bülten hazırlanma
A5: 4 | B5: Tesis adına bulgu ve ilgili ekipman denet raporu hazırlığı (kalite koordinatörlüğüne teslim) | C5: 6 saat | D5: 45936 | E5: 3 | I5: 4 | J5: temel bilimler bölümü ar gör temsilciği
A6: 5 | B6: Pearson Görevlendirmesi-Asistanlık (Sabire Cömert) | C6: 3 saat | D6: 45939 | E6: 3 | I6: 5 | J6: itü-delmar denizde canlı kalma eğitim merkezi koordinatörlüğü
A7: 6 | B7: Pearson Görevlendirmesi-Asistanlık (B. Barış Kızılsaç) | C7: 3 saat | D7: 45939 | E7: 3 | I7: 6 | J7: 4.sınıf amirliği
A8: 7 | B8: NATO ön hazırlık | C8: TÜM GÜN | D8: 45941 | E8: 4
A9: 8 | B9: NATO ön hazırlık | C9: TÜM GÜN | D9: 45942 | E9: 4
A10: 9 | B10: NATO 13-17 Ekim görevlendirme | C10: TÜM GÜN | D10: 13-17 Ekim 2025 | E10: 20
A11: 10 | B11: Pearson Görevlendirmesi-Asistanlık (Sabire Cömert) | C11: 3 saat | D11: 45946 | E11: 3 | I11: 1 NİSAN 2026 YURTDIŞINA GİDİYOR
A12: 11 | B12: Pearson Görevlendirmesi-Asistanlık (B. Barış Kızılsaç) | C12: 3 saat | D12: 45946 | E12: 3
A13: 12 | B13: Fakülte için DELMAR filikası ile eğitim verildi. | D13: 45951 | E13: 2
A14: 13 | B14: Toplantı (İTÜ E-Bülten çalışmaları) (Rektör Yrd. ile) | C14: 1 saat | D14: 45952 | E14: 1 | I14: 1 NİSAN'A KADAR İZİNLİ
A15: 14 | B15: Pearson Görevlendirmesi-Asistanlık (Sabire Cömert) | C15: 3 saat | D15: 45953 | E15: 3
A16: 15 | B16: Pearson Görevlendirmesi-Asistanlık (B. Barış Kızılsaç) | C16: 3 saat | D16: 45953 | E16: 3
A17: 16 | B17: Pearson Görevlendirmesi-Asistanlık (Sabire Cömert) | C17: 3 saat | D17: 45960 | E17: 3
A18: 17 | B18: Pearson Görevlendirmesi-Asistanlık (B. Barış Kızılsaç) | C18: 3 saat | D18: 45960 | E18: 3
A19: 18 | B19: Pearson Görevlendirmesi-Asistanlık (Sabire Cömert) | C19: 3 saat | D19: 45967 | E19: 3
A20: 19 | B20: Pearson Görevlendirmesi-Asistanlık (B. Barış Kızılsaç) | C20: 3 saat | D20: 45967 | E20: 3
A21: 20 | B21: Uzun staj için öğrenci beyanlarının kontrolü | C21: 1 saat | D21: 45972 | E21: 1
A22: 21 | B22: Pearson Görevlendirmesi-Asistanlık (Sabire Cömert) | C22: 3 saat | D22: 45973 | E22: 3
A23: 22 | B23: Pearson Görevlendirmesi-Asistanlık (B. Barış Kızılsaç) | C23: 3 saat | D23: 45973 | E23: 3
A24: 23 | B24: Tuzla haftaiçi 1 sınav (Kariyer günleri)-mesai dışı | C24: 1 saat | D24: 45973 | E24: 2
A25: 24 | B25: Ders yedekleme (Denizde Güvenlik)-Sinan Çakır | C25: 14:00-16:30 | D25: 45975 | E25: 2
A26: 25 | B26: Ders yedekleme (Tek seferlik)-Toprak Oba yerine | C26: 1 ders | D26: 45979 | E26: 2
A27: 26 | B27: Tuzla haftaiçi 1 sınav (Stabilite-Emre Hoca) | C27: 1830 | D27: 45979 | E27: 2
A28: 27 | B28: Pearson Görevlendirmesi-Asistanlık (Sabire Cömert) | C28: 3 saat | D28: 45980 | E28: 3
A29: 28 | B29: Pearson Görevlendirmesi-Asistanlık (B. Barış Kızılsaç) | C29: 3 saat | D29: 45981 | E29: 3
A30: 29 | B30: Tuzla haftasonu 1 sınav (MAT103) | C30: 2 saat | D30: 45983 | E30: 3
A31: 30 | B31: Tuzla haftaiçi 1 sınav (Buhar kazanları) | D31: 45986 | E31: 1
A32: 31 | B32: Pearson Görevlendirmesi-Asistanlık (Sabire Cömert) | C32: 3 saat | D32: 45987 | E32: 3
A33: 32 | B33: Pearson Görevlendirmesi-Asistanlık (B. Barış Kızılsaç) | C33: 3 saat | D33: 45988 | E33: 3
A34: 33 | B34: Tuzla haftasonu 1 sınav (KIM101) | C34: 2 saat | D34: 45990 | E34: 3
A35: 34 | B35: Tuzla haftasonu 1 sınav (FIZ101) | C35: 2 saat | D35: 45991 | E35: 3
A36: 35 | B36: Tuzla haftaiçi 1 sınav (Aydın Mert-MATLAB) | C36: 1800 | D36: 45993 | E36: 2
A37: 36 | B37: Tuzla haftaiçi 1 sınav (Sabire Cömert) | C37: 1730 | D37: 45994 | E37: 2
A38: 37 | B38: Pearson Görevlendirmesi-Asistanlık (Sabire Cömert) | C38: 3 saat | D38: 45995 | E38: 3
A39: 38 | B39: Pearson Görevlendirmesi-Asistanlık (B. Barış Kızılsaç) | C39: 3 saat | D39: 45996 | E39: 3
A40: 39 | B40: Pearson Görevlendirmesi-Asistanlık (Sabire Cömert) | C40: 3 saat | D40: 46001 | E40: 3
...
